2020-05-24 09:44:00.136844: W tensorflow/stream_executor/platform/default/dso_loader.cc:55] Could not load dynamic library 'libnvinfer.so.6'; dlerror: libnvinfer.so.6: cannot open shared object file: No such file or directory; LD_LIBRARY_PATH: /sw/arcts/centos7/python3.6-anaconda/5.2.0/lib:/opt/slurm/lib64::
2020-05-24 09:44:00.137502: W tensorflow/stream_executor/platform/default/dso_loader.cc:55] Could not load dynamic library 'libnvinfer_plugin.so.6'; dlerror: libnvinfer_plugin.so.6: cannot open shared object file: No such file or directory; LD_LIBRARY_PATH: /sw/arcts/centos7/python3.6-anaconda/5.2.0/lib:/opt/slurm/lib64::
2020-05-24 09:44:00.137514: W tensorflow/compiler/tf2tensorrt/utils/py_utils.cc:30] Cannot dlopen some TensorRT libraries. If you would like to use Nvidia GPU with TensorRT, please make sure the missing libraries mentioned above are installed properly.
2020-05-24 09:44:18.796625: W tensorflow/stream_executor/platform/default/dso_loader.cc:55] Could not load dynamic library 'libcuda.so.1'; dlerror: libcuda.so.1: cannot open shared object file: No such file or directory; LD_LIBRARY_PATH: /sw/arcts/centos7/python3.6-anaconda/5.2.0/lib:/opt/slurm/lib64::
2020-05-24 09:44:18.796799: E tensorflow/stream_executor/cuda/cuda_driver.cc:351] failed call to cuInit: UNKNOWN ERROR (303)
2020-05-24 09:44:18.796824: I tensorflow/stream_executor/cuda/cuda_diagnostics.cc:156] kernel driver does not appear to be running on this host (gl3038.arc-ts.umich.edu): /proc/driver/nvidia/version does not exist
2020-05-24 09:44:18.797194: I tensorflow/core/platform/cpu_feature_guard.cc:142] Your CPU supports instructions that this TensorFlow binary was not compiled to use: AVX2 AVX512F FMA
2020-05-24 09:44:18.804452: I tensorflow/core/platform/profile_utils/cpu_utils.cc:94] CPU Frequency: 3000000000 Hz
2020-05-24 09:44:18.804947: I tensorflow/compiler/xla/service/service.cc:168] XLA service 0x556101db3830 initialized for platform Host (this does not guarantee that XLA will be used). Devices:
2020-05-24 09:44:18.804962: I tensorflow/compiler/xla/service/service.cc:176]   StreamExecutor device (0): Host, Default Version
Done step 200

Done step 400

Done step 600

Done step 800

Done step 1000

Done step 1200

Done step 1400

Done step 1600

Done step 1800

Done step 2000

Done step 2200

Done step 2400

Done step 2600

Done step 2800

Done step 3000

Done step 3200

Done step 3400

Done step 3600

Done step 3800

Done step 4000

Done step 4200

Done step 4400

Done step 4600

Done step 4800

Done step 5000

Done step 5200

Done step 5400

Done step 5600

Done step 5800

Done step 6000

Done step 6200

Done step 6400

Done step 6600

Done step 6800

Done step 7000

Done step 7200

Done step 7400

Done step 7600

Done step 7800

Done step 8000

Done step 8200

Done step 8400

Done step 8600

Done step 8800

Done step 9000

Done step 9200

Done step 9400

Done step 9600

Done step 9800

Done step 10000

Number of cpus : 36
/sw/arcts/centos7/python3.6-anaconda/5.2.0/lib/python3.6/site-packages/h5py/__init__.py:36: FutureWarning: Conversion of the second argument of issubdtype from `float` to `np.floating` is deprecated. In future, it will be treated as `np.float64 == np.dtype(float).type`.
  from ._conv import register_converters as _register_converters
Traceback (most recent call last):
  File "adversarial_sample.py", line 86, in <module>
    np.save(filename, perturbed_test_samples)
  File "/sw/arcts/centos7/python3.6-anaconda/5.2.0/lib/python3.6/site-packages/numpy/lib/npyio.py", line 524, in save
    fid = open(file, "wb")
FileNotFoundError: [Errno 2] No such file or directory: 'adversarial-points/perturbed_test_points_1.npy'
2020-05-24 09:48:16.484787: W tensorflow/stream_executor/platform/default/dso_loader.cc:55] Could not load dynamic library 'libnvinfer.so.6'; dlerror: libnvinfer.so.6: cannot open shared object file: No such file or directory; LD_LIBRARY_PATH: /sw/arcts/centos7/python3.6-anaconda/5.2.0/lib:/opt/slurm/lib64::
2020-05-24 09:48:16.484907: W tensorflow/stream_executor/platform/default/dso_loader.cc:55] Could not load dynamic library 'libnvinfer_plugin.so.6'; dlerror: libnvinfer_plugin.so.6: cannot open shared object file: No such file or directory; LD_LIBRARY_PATH: /sw/arcts/centos7/python3.6-anaconda/5.2.0/lib:/opt/slurm/lib64::
2020-05-24 09:48:16.484921: W tensorflow/compiler/tf2tensorrt/utils/py_utils.cc:30] Cannot dlopen some TensorRT libraries. If you would like to use Nvidia GPU with TensorRT, please make sure the missing libraries mentioned above are installed properly.
2020-05-24 09:48:19.538677: W tensorflow/stream_executor/platform/default/dso_loader.cc:55] Could not load dynamic library 'libcuda.so.1'; dlerror: libcuda.so.1: cannot open shared object file: No such file or directory; LD_LIBRARY_PATH: /sw/arcts/centos7/python3.6-anaconda/5.2.0/lib:/opt/slurm/lib64::
2020-05-24 09:48:19.538715: E tensorflow/stream_executor/cuda/cuda_driver.cc:351] failed call to cuInit: UNKNOWN ERROR (303)
2020-05-24 09:48:19.538741: I tensorflow/stream_executor/cuda/cuda_diagnostics.cc:156] kernel driver does not appear to be running on this host (gl3038.arc-ts.umich.edu): /proc/driver/nvidia/version does not exist
2020-05-24 09:48:19.539059: I tensorflow/core/platform/cpu_feature_guard.cc:142] Your CPU supports instructions that this TensorFlow binary was not compiled to use: AVX2 AVX512F FMA
2020-05-24 09:48:19.546295: I tensorflow/core/platform/profile_utils/cpu_utils.cc:94] CPU Frequency: 3000000000 Hz
2020-05-24 09:48:19.547120: I tensorflow/compiler/xla/service/service.cc:168] XLA service 0x55dc1b936ad0 initialized for platform Host (this does not guarantee that XLA will be used). Devices:
2020-05-24 09:48:19.547154: I tensorflow/compiler/xla/service/service.cc:176]   StreamExecutor device (0): Host, Default Version
Done step 200

Done step 400

Done step 600

Done step 800

Done step 1000

Done step 1200

Done step 1400

Done step 1600

Done step 1800

Done step 2000

Done step 2200

Done step 2400

Done step 2600

Done step 2800

Done step 3000

Done step 3200

Done step 3400

Done step 3600

Done step 3800

Done step 4000

Done step 4200

Done step 4400

Done step 4600

Done step 4800

Done step 5000

Done step 5200

Done step 5400

Done step 5600

Done step 5800

Done step 6000

Done step 6200

Done step 6400

Done step 6600

Done step 6800

Done step 7000

Done step 7200

Done step 7400

Done step 7600

Done step 7800

Done step 8000

Done step 8200

Done step 8400

Done step 8600

Done step 8800

Done step 9000

Done step 9200

Done step 9400

Done step 9600

Done step 9800

Done step 10000

Number of cpus : 36
/sw/arcts/centos7/python3.6-anaconda/5.2.0/lib/python3.6/site-packages/h5py/__init__.py:36: FutureWarning: Conversion of the second argument of issubdtype from `float` to `np.floating` is deprecated. In future, it will be treated as `np.float64 == np.dtype(float).type`.
  from ._conv import register_converters as _register_converters
Traceback (most recent call last):
  File "adversarial_sample_fair.py", line 87, in <module>
    np.save(filename, perturbed_test_samples)
  File "/sw/arcts/centos7/python3.6-anaconda/5.2.0/lib/python3.6/site-packages/numpy/lib/npyio.py", line 524, in save
    fid = open(file, "wb")
FileNotFoundError: [Errno 2] No such file or directory: 'adversarial-points/perturbed_test_points_1_fair.npy'
